<?xml version="1.0" encoding="utf-8"?>
<!-- This URDF was automatically created by SolidWorks to URDF Exporter! Originally created by Stephen Brawner (brawner@gmail.com) 
     Commit Version: 1.5.1-0-g916b5db  Build Version: 1.5.7152.31018
     For more information, please see http://wiki.ros.org/sw_urdf_exporter -->
<robot
  name="mysiasun">
  <link
    name="base_link">
    <inertial>
      <origin
        xyz="-4.8007E-13 -6.9706E-12 0.11321"
        rpy="0 0 0" />
      <mass
        value="14.928" />
      <inertia
        ixx="0.2462"
        ixy="-9.7488E-13"
        ixz="3.4123E-12"
        iyy="0.2462"
        iyz="-5.4948E-11"
        izz="0.37646" />
    </inertial>
    <visual>
      <origin
        xyz="0 0 0"
        rpy="0 0 0" />
      <geometry>
        <mesh
          filename="package://mysiasun/meshes/base_link.STL" />
      </geometry>
      <material
        name="">
        <color
          rgba="1 1 1 1" />
      </material>
    </visual>
    <collision>
      <origin
        xyz="0 0 0"
        rpy="0 0 0" />
      <geometry>
        <mesh
          filename="package://mysiasun/meshes/base_link.STL" />
      </geometry>
    </collision>
  </link>
  <link
    name="link1">
    <inertial>
      <origin
        xyz="0.13933 -0.023413 0.20748"
        rpy="0 0 0" />
      <mass
        value="24.748" />
      <inertia
        ixx="0.56826"
        ixy="-0.1452"
        ixz="-0.14122"
        iyy="0.82673"
        iyz="-0.035095"
        izz="0.866" />
    </inertial>
    <visual>
      <origin
        xyz="0 0 0"
        rpy="0 0 0" />
      <geometry>
        <mesh
          filename="package://mysiasun/meshes/link1.STL" />
      </geometry>
      <material
        name="">
        <color
          rgba="1 1 1 1" />
      </material>
    </visual>
    <collision>
      <origin
        xyz="0 0 0"
        rpy="0 0 0" />
      <geometry>
        <mesh
          filename="package://mysiasun/meshes/link1.STL" />
      </geometry>
    </collision>
  </link>
  <joint
    name="joint1"
    type="revolute">
    <origin
      xyz="0 0 0.23333"
      rpy="0 0 0" />
    <parent
      link="base_link" />
    <child
      link="link1" />
    <axis
      xyz="0 0 1" />
    <limit
      lower="-3.1416"
      upper="3.1416"
      effort="0"
      velocity="0" />
  </joint>
  <link
    name="link2">
    <inertial>
      <origin
        xyz="0.026218 -0.32284 -0.19106"
        rpy="0 0 0" />
      <mass
        value="13.345" />
      <inertia
        ixx="0.9581"
        ixy="0.0022928"
        ixz="0.0035092"
        iyy="0.15055"
        iyz="0.039264"
        izz="1.0256" />
    </inertial>
    <visual>
      <origin
        xyz="0 0 0"
        rpy="0 0 0" />
      <geometry>
        <mesh
          filename="package://mysiasun/meshes/link2.STL" />
      </geometry>
      <material
        name="">
        <color
          rgba="1 1 1 1" />
      </material>
    </visual>
    <collision>
      <origin
        xyz="0 0 0"
        rpy="0 0 0" />
      <geometry>
        <mesh
          filename="package://mysiasun/meshes/link2.STL" />
      </geometry>
    </collision>
  </link>
  <joint
    name="joint2"
    type="revolute">
    <origin
      xyz="0.26667 0 0.29333"
      rpy="-1.5708 0 0" />
    <parent
      link="link1" />
    <child
      link="link2" />
    <axis
      xyz="0 0 1" />
    <limit
      lower="-1.2476"
      upper="1.2832"
      effort="0"
      velocity="0" />
  </joint>
  <link
    name="link3">
    <inertial>
      <origin
        xyz="0.16312891685154 0.0027846978022037 0.0104476636920152"
        rpy="0 0 0" />
      <mass
        value="31.5720830735543" />
      <inertia
        ixx="0.212082183328278"
        ixy="0.00334208996311578"
        ixz="-0.00703700090905689"
        iyy="0.907574610275585"
        iyz="-0.00148647679660032"
        izz="0.981799844618562" />
    </inertial>
    <visual>
      <origin
        xyz="0 0 0"
        rpy="0 0 0" />
      <geometry>
        <mesh
          filename="package://mysiasun/meshes/link3.STL" />
      </geometry>
      <material
        name="">
        <color
          rgba="1 1 1 1" />
      </material>
    </visual>
    <collision>
      <origin
        xyz="0 0 0"
        rpy="0 0 0" />
      <geometry>
        <mesh
          filename="package://mysiasun/meshes/link3.STL" />
      </geometry>
    </collision>
  </link>
  <joint
    name="joint3"
    type="revolute">
    <origin
      xyz="0 -0.66667 0"
      rpy="0 0 0" />
    <parent
      link="link2" />
    <child
      link="link3" />
    <axis
      xyz="0 0 1" />
    <limit
      lower="-3.5643"
      upper="1.1481"
      effort="0"
      velocity="0" />
  </joint>
  <link
    name="link4">
    <inertial>
      <origin
        xyz="2.1678E-08 0.0016302 0.75842"
        rpy="0 0 0" />
      <mass
        value="2.9322" />
      <inertia
        ixx="0.01925"
        ixy="2.5621E-08"
        ixz="1.1141E-08"
        iyy="0.015446"
        iyz="-0.00020916"
        izz="0.016358" />
    </inertial>
    <visual>
      <origin
        xyz="0 0 0"
        rpy="0 0 0" />
      <geometry>
        <mesh
          filename="package://mysiasun/meshes/link4.STL" />
      </geometry>
      <material
        name="">
        <color
          rgba="1 1 1 1" />
      </material>
    </visual>
    <collision>
      <origin
        xyz="0 0 0"
        rpy="0 0 0" />
      <geometry>
        <mesh
          filename="package://mysiasun/meshes/link4.STL" />
      </geometry>
    </collision>
  </link>
  <joint
    name="joint4"
    type="revolute">
    <origin
      xyz="0 0 0"
      rpy="-1.5708 0 -1.5708" />
    <parent
      link="link3" />
    <child
      link="link4" />
    <axis
      xyz="0 0 1" />
    <limit
      lower="-3.1416"
      upper="3.1416"
      effort="0"
      velocity="0" />
  </joint>
  <link
    name="link5">
    <inertial>
      <origin
        xyz="-5.0048E-08 0.011531 -0.0027047"
        rpy="0 0 0" />
      <mass
        value="1.4499" />
      <inertia
        ixx="0.0029576"
        ixy="-3.5869E-10"
        ixz="-1.8738E-09"
        iyy="0.0032638"
        iyz="1.0282E-05"
        izz="0.0036646" />
    </inertial>
    <visual>
      <origin
        xyz="0 0 0"
        rpy="0 0 0" />
      <geometry>
        <mesh
          filename="package://mysiasun/meshes/link5.STL" />
      </geometry>
      <material
        name="">
        <color
          rgba="0.79216 0.81961 0.93333 1" />
      </material>
    </visual>
    <collision>
      <origin
        xyz="0 0 0"
        rpy="0 0 0" />
      <geometry>
        <mesh
          filename="package://mysiasun/meshes/link5.STL" />
      </geometry>
    </collision>
  </link>
  <joint
    name="joint5"
    type="revolute">
    <origin
      xyz="0 0 0.87133"
      rpy="1.5708 0 0" />
    <parent
      link="link4" />
    <child
      link="link5" />
    <axis
      xyz="0 0 1" />
    <limit
      lower="-1.92"
      upper="1.92"
      effort="0"
      velocity="0" />
  </joint>
  <link
    name="link6">
    <inertial>
      <origin
        xyz="4.402E-05 -3.3766E-06 0.18695"
        rpy="0 0 0" />
      <mass
        value="0.84592" />
      <inertia
        ixx="0.0011741"
        ixy="3.3504E-09"
        ixz="4.006E-09"
        iyy="0.0010505"
        iyz="2.6353E-10"
        izz="0.0011497" />
    </inertial>
    <visual>
      <origin
        xyz="0 0 0"
        rpy="0 0 0" />
      <geometry>
        <mesh
          filename="package://mysiasun/meshes/link6.STL" />
      </geometry>
      <material
        name="">
        <color
          rgba="1 1 1 1" />
      </material>
    </visual>
    <collision>
      <origin
        xyz="0 0 0"
        rpy="0 0 0" />
      <geometry>
        <mesh
          filename="package://mysiasun/meshes/link6.STL" />
      </geometry>
    </collision>
  </link>
  <joint
    name="joint6"
    type="revolute">
    <origin
      xyz="0 0 0"
      rpy="-1.5708 0 0" />
    <parent
      link="link5" />
    <child
      link="link6" />
    <axis
      xyz="0 0 1" />
    <limit
      lower="-3.14"
      upper="3.14"
      effort="0"
      velocity="0" />
  </joint>
  <link
    name="end">
    <inertial>
      <origin
        xyz="1.1102E-16 -1.9439E-19 -0.05"
        rpy="0 0 0" />
      <mass
        value="0.007854" />
      <inertia
        ixx="6.5941E-06"
        ixy="-3.4466E-25"
        ixz="6.6058E-22"
        iyy="6.5941E-06"
        iyz="2.4926E-23"
        izz="9.8175E-08" />
    </inertial>
    <visual>
      <origin
        xyz="0 0 0"
        rpy="0 0 0" />
      <geometry>
        <mesh
          filename="package://mysiasun/meshes/end.STL" />
      </geometry>
      <material
        name="">
        <color
          rgba="1 1 1 1" />
      </material>
    </visual>
    <collision>
      <origin
        xyz="0 0 0"
        rpy="0 0 0" />
      <geometry>
        <mesh
          filename="package://mysiasun/meshes/end.STL" />
      </geometry>
    </collision>
  </link>
  <joint
    name="end"
    type="fixed">
    <origin
      xyz="0 0 0.40667"
      rpy="0 0 0" />
    <parent
      link="link6" />
    <child
      link="end" />
    <axis
      xyz="0 0 0" />
  </joint>
</robot>